Workbook

Sheet Instructions
A1: DATA AGENT EVALUATION TEMPLATE
A3: Sheet | B3: Purpose | C3: Who fills
A4: Gold_Dataset | B4: Test questions + ground truth SQL + expected results | C4: DA Team
A5: Agent_A_Results | B5: Output from Agent A (existing agent) | C5: Auto / Evaluator
A6: Agent_B_Results | B6: Output from Agent B (new agent) | C6: Auto / Evaluator
A7: Evaluation_Scores | B7: Per-question scoring for both agents | C7: Evaluator + Formulas
A8: Head_to_Head | B8: Pairwise comparison & statistical summary | C8: Formulas
A9: Error_Analysis | B9: Failure categorization & root cause | C9: Evaluator
A10: Summary_Dashboard | B10: Aggregated metrics & final report | C10: Formulas
A12: COLOR LEGEND
A13: Yellow cells | B13: Input required — fill these in
A14: Green cells | B14: Auto-calculated by formulas
A15: Gray cells | B15: Reference / locked — do not edit
A17: WORKFLOW
A18: Step 1 | B18: Fill Gold_Dataset with real questions + gold SQL from DA team
A19: Step 2 | B19: Run both agents, paste outputs into Agent_A/B_Results sheets
A20: Step 3 | B20: Fill Evaluation_Scores (some auto, some manual judgment)
A21: Step 4 | B21: Review Head_to_Head and Summary_Dashboard for results
A22: Step 5 | B22: Fill Error_Analysis for failures to guide improvements

Sheet README FIRST
A1: Giải thích từng cột, từng sheet Sheet 1: Gold_Dataset Đây là foundation — mọi sheet khác đều reference ngược về đây. Chất lượng eval phụ thuộc hoàn toàn vào chất lượng sheet này. ID — mã định danh duy nhất cho mỗi test case (Q001, Q002...). Convention nào cũng được, miễn unique. Tất cả sheets khác dùng ID này để cross-reference. Question (NL) — câu hỏi bằng ngôn ngữ tự nhiên, đúng như cách user/stakeholder thực sự hỏi. Không được "clean up" hay rephrase cho rõ ràng hơn, vì bạn đang test khả năng agent hiểu ngôn ngữ thực tế. Ví dụ: "cho t biết GMV tháng rồi chia theo category" chứ không phải "Tính tổng GMV tháng 1/2025 group by category_name từ bảng orders". Category — phân loại pattern SQL mà câu hỏi yêu cầu. Mục đích là sau này breakdown performance theo từng pattern để biết agent yếu ở đâu. Các giá trị: Aggregation: SUM, COUNT, AVG, GROUP BY Ranking + Filter: TOP N, HAVING, ORDER BY + LIMIT JOIN: multi-table queries Window + Complex: window functions (ROW_NUMBER, LAG, LEAD), CTEs Subquery: nested SELECT Date/Time: date ranges, date math, timezone handling Conditional Logic: CASE WHEN, IF Multi-step: cần nhiều bước logic, kết hợp nhiều pattern trên Ambiguous: câu hỏi cố tình mơ hồ, test khả năng agent hỏi lại Một question có thể thuộc nhiều category — chọn category dominant nhất. Difficulty — độ khó, dùng để stratify kết quả. Tiêu chí phân loại: Simple: 1 table, basic WHERE/GROUP BY, không JOIN Moderate: 2-3 JOINs, hoặc có subquery/HAVING Complex: CTEs, window functions, nested aggregations, business logic phức tạp Ambiguous: câu hỏi không đủ thông tin để viết SQL duy nhất — agent đúng khi hỏi lại thay vì đoán Target Tables — danh sách tables mà gold SQL cần dùng. Đây là ground truth cho metric Schema Linking — nếu agent dùng đúng tables này thì schema linking đúng. Liệt kê comma-separated. Target Columns — tương tự, các columns quan trọng trong gold SQL. Không cần liệt kê hết mọi column, chỉ cần các columns mang semantic meaning (columns trong SELECT, WHERE, JOIN conditions). Business Rules / Notes — các implicit rules mà agent cần biết để viết SQL đúng. Đây là phần hay bị miss nhất. Ví dụ: "GMV chỉ tính orders có status='completed'", "active user = có ít nhất 1 transaction trong 30 ngày", "soft delete dùng cột is_deleted". Nếu gold SQL phụ thuộc vào business rule mà không có trong schema, ghi ở đây. Gold SQL — SQL chuẩn do DA team viết. Đây là reference answer, không phải unique answer. Hai SQL khác nhau hoàn toàn nhưng ra cùng result đều đúng. Gold SQL dùng cho 2 mục đích: so sánh result set (primary) và so sánh efficiency/readability (secondary). Gold Result (summary) — mô tả tóm tắt kết quả khi chạy gold SQL. Không cần paste full result set, chỉ cần đủ để verify nhanh: "5 rows, total GMV = 12.5B", "empty result set", "1 row, value = 42.3%". Nếu result lớn, ghi pattern thay vì data cụ thể. Expected Row Count — số rows trả về. Dùng làm quick sanity check — nếu agent trả 1000 rows mà expected là 10, chắc chắn sai mà không cần so sánh chi tiết. Dataset Split — quan trọng nhất về mặt methodology: dev: dùng trong quá trình develop, iterate, debug agent. Được phép nhìn đi nhìn lại, tune prompt dựa trên kết quả eval: held-out set, chỉ chạy khi muốn đo chính thức. Không bao giờ dùng để guide development decisions ambiguous: subset riêng cho câu hỏi mơ hồ, đánh giá khả năng clarification Sheet 2 & 3: Agent_A_Results / Agent_B_Results Cấu trúc giống nhau, mỗi sheet chứa output của một agent. A = agent hiện tại (baseline), B = agent mới. ID — auto-link từ Gold_Dataset. Không sửa. Question (ref) — auto-link câu hỏi từ Gold_Dataset. Để tiện đọc mà không phải switch sheet. Generated SQL — SQL mà agent sinh ra. Paste nguyên văn, kể cả nếu sai syntax. Đây là raw output, không chỉnh sửa. Execution Status — kết quả khi chạy generated SQL trên DB: SUCCESS: parse + execute thành công, có result SYNTAX_ERROR: SQL không parse được (thiếu comma, sai keyword...) RUNTIME_ERROR: parse OK nhưng execute fail (column not found, type mismatch...) TIMEOUT: query chạy quá lâu, bị kill EMPTY_RESULT: execute OK nhưng 0 rows — có thể đúng (nếu gold cũng 0) hoặc sai HALLUCINATION: reference table hoặc column không tồn tại trong schema. Đây là failure mode nghiêm trọng nhất vì agent "bịa" ra thứ không có Query Result (summary) — tóm tắt result tương tự cột Gold Result. Dùng để eyeball comparison nhanh. Result Row Count — số rows trả về. So với Expected Row Count ở Gold_Dataset. Execution Time (ms) — thời gian execute query, tính bằng milliseconds. Dùng cho latency comparison và efficiency evaluation. Nếu agent A trả đúng trong 200ms nhưng agent B cần 15 giây, đó là signal quan trọng. Tables Used — liệt kê tables mà generated SQL thực sự dùng. So với Target Tables ở Gold_Dataset → tính Schema Linking accuracy. Nếu agent dùng đúng tables nhưng sai columns, vấn đề ở level khác vs dùng sai tables hoàn toàn. Columns Used — tương tự cho columns. Agent Confidence Score — nếu agent có output confidence/probability thì ghi ở đây. Dùng để phân tích calibration: agent nói 95% confident nhưng sai 40% thì calibration tệ. Nếu agent không output confidence thì để trống. Retries / Self-corrections — số lần agent tự retry khi gặp lỗi. Ví dụ: SQL đầu tiên syntax error → agent tự sửa → lần 2 chạy OK. Ghi "1 retry, fixed syntax". Metric này đo agentic loop quality — agent tốt phải biết self-correct. Error Message (if any) — error message từ DB khi execute fail. Paste nguyên văn. Ví dụ: ERROR: column "user_name" does not exist. Did you mean "username"?. Giúp phân loại error pattern ở sheet Error_Analysis. Notes — ghi chú tự do. Ví dụ: "SQL đúng nhưng dùng full table scan", "agent hỏi lại 1 lần trước khi generate", "result đúng nhưng column order khác gold". Sheet 4: Evaluation_Scores Đây là sheet scoring chính, nơi mọi metric được tính cho từng question. ID, Difficulty, Category — auto-link từ Gold_Dataset. Context để breakdown sau này. A/B: Valid SQL (formula, auto) — binary 1/0. Tự tính từ Execution Status ở Agent Results: SUCCESS → 1, mọi thứ khác → 0. Đây là prerequisite metric — nếu SQL không valid thì các metric khác không applicable. A/B: Exact Result Match (manual) — binary 1/0. Bạn so sánh result set của agent với gold result. 1 = result sets identical (order-insensitive), 0 = khác. Đây là metric quan trọng nhất trong toàn bộ eval. Lưu ý: 2 SQL hoàn toàn khác nhau có thể cho cùng result → cả hai đều score 1. A/B: Partial Credit (manual) — số từ 0.0 đến 1.0. Dùng khi result không exact match nhưng "gần đúng". Cách tính: bao nhiêu % columns trong SELECT đúng × bao nhiêu % rows đúng. Ví dụ: gold trả 5 columns 10 rows, agent trả đúng 4 columns 10 rows → partial credit ≈ 0.8. Metric này tránh binary harsh judgment — agent sai 1 column nhưng đúng 90% vẫn nên được credit. A/B: Schema Linking (manual) — số từ 0.0 đến 1.0. So sánh tables + columns mà agent dùng vs Target Tables/Columns ở Gold_Dataset. Tính bằng F1 score: precision (bao nhiêu % tables agent dùng là đúng) × recall (bao nhiêu % tables cần dùng mà agent dùng). Diagnostic metric — nếu cái này thấp, vấn đề nằm ở schema retrieval/understanding, không phải SQL generation. A/B: Efficiency Score (manual) — số từ 0.0 đến 1.0. Đánh giá chất lượng SQL khi cả 2 đều ra đúng result. Criteria: có dùng index không, có unnecessary full table scan không, có redundant subquery không, execution time so với gold SQL. Scoring guide: 1.0 = ngang hoặc tốt hơn gold, 0.7 = acceptable nhưng suboptimal, 0.3 = chạy được nhưng sẽ có vấn đề trên production data, 0.0 = timeout hoặc resource-intensive đến mức không dùng được. Winner (EX) (formula, auto) — so sánh Exact Result Match giữa A và B cho question đó. A nếu A đúng B sai, B nếu ngược lại, Tie nếu cả hai cùng đúng hoặc cùng sai. Winner (Overall) (manual) — đánh giá tổng hợp khi xét tất cả metrics. Có thể khác Winner (EX) — ví dụ cả 2 đều exact match nhưng B hiệu quả hơn nhiều → Overall winner = B. LLM Judge Score (manual) — điểm từ LLM-as-Judge nếu bạn dùng. Paste score hoặc verdict (A/B/Tie) từ judge model. Optional nhưng hữu ích cho cases mà cả 2 đều "đúng" nhưng quality khác nhau. Notes — ghi chú cho scoring decisions không rõ ràng. Ví dụ: "Cả 2 result gần giống, A thiếu 1 row do filter condition khác". Sheet 5: Head_to_Head Tự động tính toàn bộ từ Evaluation_Scores. Không cần điền gì. McNemar's Contingency Table — bảng 2×2 đếm 4 trường hợp: Both Correct (a): cả A và B đều exact match. Không cho biết agent nào tốt hơn A Correct, B Wrong (b): cases mà A thắng. Đây là competitive advantage của A A Wrong, B Correct (c): cases mà B thắng. Đây là improvement của B so với A Both Wrong (d): cả 2 đều fail. Hardest cases, cần fundamentally different approach McNemar Statistic (χ²) — (b - c)² / (b + c). Chỉ xét ô b và c (disagreement cells), bỏ qua a và d. Logic: nếu 2 agents thực sự ngang nhau, b và c nên gần bằng nhau. Nếu χ² lớn → khác biệt có ý nghĩa thống kê. Critical value — 3.841 (chi-square, df=1, α=0.05). Nếu χ² > 3.841 thì p < 0.05, reject null hypothesis rằng 2 agents ngang nhau. Significant? — YES/NO dựa trên so sánh χ² với critical value. Nếu NO thì khác biệt có thể chỉ là noise, cần thêm data hoặc chấp nhận 2 agents ngang nhau. Breakdown by Difficulty — với mỗi level (Simple/Moderate/Complex/Ambiguous): N: số questions thuộc level đó Agent A/B EX Acc: % exact match cho level đó Δ (B - A): chênh lệch. Dương = B tốt hơn Winner: agent nào win ở level này Ý nghĩa: agent B có thể overall tốt hơn 5% nhưng thực ra chỉ win ở Simple queries (+10%) và thua ở Complex (-8%). Breakdown cho bạn thấy điều này. Breakdown by Category — logic tương tự nhưng chia theo query pattern thay vì difficulty. Cho biết agent mạnh/yếu ở pattern SQL nào cụ thể. Sheet 6: Error_Analysis Sheet quan trọng nhất cho actionable improvements. Mỗi row là một failure case. ID — link về question nào. Agent — failure này của agent nào (A, B, hoặc Both). Error Category — phân loại gốc rễ lỗi: Schema Linking: chọn sai table hoặc column SQL Syntax: SQL không parse được Logic Error: syntax OK, chạy được, nhưng logic sai (sai JOIN condition, sai aggregation, thiếu filter) Hallucination: reference thứ không tồn tại Timeout: query quá chậm Ambiguity Handling: câu hỏi mơ hồ mà agent không hỏi lại, đoán sai Efficiency: result đúng nhưng SQL quá chậm / resource-intensive Other: không thuộc category trên Error Subcategory — chi tiết hơn. Ví dụ trong Schema Linking: "wrong table" vs "right table wrong column" vs "missing JOIN table". Trong Logic Error: "wrong aggregation function" vs "missing WHERE condition" vs "wrong JOIN type". Bạn tự define subcategories dựa trên patterns bạn thấy. Description — mô tả cụ thể lỗi gì xảy ra. Ví dụ: "Agent dùng LEFT JOIN thay vì INNER JOIN, khiến result chứa NULL rows từ merchants không có orders". Root Cause — tại sao agent mắc lỗi này. Đây là phần cần suy nghĩ sâu. Ví dụ: "Schema context không chứa thông tin về relationship cardinality giữa orders và merchants", "Business rule 'chỉ tính completed orders' không có trong prompt", "Agent không xử lý được câu hỏi có 2 ý nghĩa". Severity — mức độ nghiêm trọng: Critical: result hoàn toàn sai hoặc misleading, có thể gây quyết định sai High: result sai đáng kể nhưng user có thể nhận ra Medium: result gần đúng, thiếu một phần nhỏ Low: result đúng nhưng SQL suboptimal Reproducible? — chạy lại cùng input có ra cùng lỗi không. Yes = deterministic bug, fix được chắc chắn. Sometimes = non-deterministic (do temperature, randomness) — cần nhiều runs để confirm. No = flaky, có thể do external factors. Fix Priority — P0 đến P3: P0: fix ngay, blocking. Ví dụ: hallucination rate > 10% P1: fix trong sprint này. Ví dụ: systematic schema linking failure trên 1 table cluster P2: fix khi có bandwidth. Ví dụ: efficiency issues trên complex queries P3: nice to have. Ví dụ: formatting khác gold nhưng result đúng Suggested Fix — đề xuất cụ thể. Ví dụ: "Thêm foreign key descriptions vào schema context", "Thêm few-shot example cho window function pattern", "Thêm business rule X vào system prompt". Sheet 7: Summary_Dashboard Tổng hợp mọi thứ, tự tính hoàn toàn bằng formulas. Overall Metrics table — mỗi row là một metric, so sánh A vs B: Total Questions: tổng số questions đã eval Valid SQL Rate: % queries không bị syntax/runtime error. Nếu dưới 90% thì agent có fundamental problem Execution Accuracy (EX): % exact result match — metric số 1 Avg Partial Credit: trung bình partial credit score, cho nuanced view hơn binary EX Schema Linking Acc: trung bình schema linking, diagnostic Avg Efficiency: trung bình efficiency score Hallucination Rate: % queries hallucinate. Nên dưới 3%. Trên 5% là red flag Avg Latency: trung bình execution time Δ (B - A) — chênh lệch. Dương = B tốt hơn. Cột Winner cho biết ai win metric đó. Statistical Significance — reference McNemar result từ Head_to_Head. Nhắc bạn rằng delta có thể chỉ là noise nếu không significant. Head-to-Head Win/Loss — 4 con số từ contingency table. Cho bạn bức tranh nhanh nhất: nếu "B wins" >> "A wins" → B tốt hơn rõ ràng.

Sheet Gold_Dataset
A1: ID | B1: Question (NL) | C1: Category | D1: Difficulty | E1: Target Tables | F1: Target Columns | G1: Business Rules / Notes | H1: Gold SQL | I1: Gold Result (summary) | J1: Expected Row Count | K1: Dataset Split | L1: Created By | M1: Created Date | N1: DOMAIN
A2: Q1 | B2: Trong 30 ngay truoc giai ngan, user thuong access bao nhieu lan? Phan bo theo bucket. | C2: Subquery | D2: Moderate | E2: momovn-prod.BU_FI.BAOTU_VAYNHANH_LOAN_INFO, momovn-prod.BU_FI.BAOTU_VAYNHANH_ENTRY_POINT | F2: AGENT_ID, LOAN_ID, DISBURSED_TIME, DISBURSED_DATE, LOAN_AMOUNT, FINAL_SEGMENT_USER, EVENT_TIME | G2: Join ENTRY_POINT within 30 days before DISBURSED_TIME using TIMESTAMP_SUB. Count accesses and distinct access days per LOAN_ID. Bucket into 1/2/3/4-5/6-10/11-20/21-50/50+. | H2: WITH disbursed_feb AS (SELECT AGENT_ID, LOAN_ID, DISBURSED_TIME, LOAN_AMOUNT, FINAL_SEGMENT_USER FROM `momovn-prod.BU_FI.BAOTU_VAYNHANH_LOAN_INFO` WHERE DISBURSED_DATE BETWEEN '2026-02-01' AND '2026-02-28' AND DISBURSED_DATE IS NOT NULL), access_counts AS (SELECT d.LOAN_ID, d.AGENT_ID, d.FINAL_SEGMENT_USER, d.LOAN_AMOUNT, COUNT(*) AS access_count, COUNT(DISTINCT DATE(e.EVENT_TIME)) AS access_days FROM disbursed_feb d JOIN `momovn-prod.BU_FI.BAOTU_VAYNHANH_ENTRY_POINT` e ON d.AGENT_ID=e.AGENT_ID AND e.EVENT_TIME<d.DISBURSED_TIME AND e.EVENT_TIME>=TIMESTAMP_SUB(d.DISBURSED_TIME, INTERVAL 30 DAY) GROUP BY d.LOAN_ID, d.AGENT_ID, d.FINAL_SEGMENT_USER, d.LOAN_AMOUNT) SELECT CASE WHEN access_count=1 THEN '01_1 lan' WHEN access_count=2 THEN '02_2 lan' WHEN access_count=3 THEN '03_3 lan' WHEN access_count BETWEEN 4 AND 5 THEN '04_4-5 lan' WHEN access_count BETWEEN 6 AND 10 THEN '05_6-10 lan' WHEN access_count BETWEEN 11 AND 20 THEN '06_11-20 lan' WHEN access_count BETWEEN 21 AND 50 THEN '07_21-50 lan' ELSE '08_50+ lan' END AS access_bucket, COUNT(*) AS loans, ROUND(100.0*COUNT(*)/SUM(COUNT(*)) OVER(),1) AS pct, ROUND(AVG(access_count),1) AS avg_accesses, ROUND(AVG(access_days),1) AS avg_days, ROUND(AVG(LOAN_AMOUNT)/1e6,1) AS avg_loan_mm FROM access_counts GROUP BY access_bucket ORDER BY access_bucket | I2: 88.4% user access >=2 lan. Top bucket: 6-10 lan (19.6%), 11-20 lan (18.0%). Avg loan tang tu 15.7M (1 lan) den 19.4M (50+ lan). Chi 11.6% quyet dinh ngay lan dau. | J2: 8 | K2: eval | L2: DA-SQL Agent | M2: 2026-03-11 | N2: VAYNHANH
A3: Q2 | B3: Tính last touchpoint user giải ngân tháng 2 | C3: Window + Complex | D3: Complex | E3: momovn-prod.BU_FI.BAOTU_VAYNHANH_LOAN_INFO, momovn-prod.BU_FI.BAOTU_VAYNHANH_ENTRY_POINT | F3: AGENT_ID, LOAN_ID, DISBURSED_TIME, DISBURSED_DATE, LOAN_AMOUNT, ACCESSED_SOURCE, EVENT_TIME, ETL_DATE | G3: Giải ngân = DISBURSED_DATE IS NOT NULL (cả STATUS DISBURSED và LIQUIDATED). Last touchpoint = ENTRY_POINT row có EVENT_TIME lớn nhất trước DISBURSED_TIME, match bằng AGENT_ID. ETL_DATE >= 2026-01-01 để giới hạn scan. | H3: WITH disbursed_feb AS ( SELECT AGENT_ID, LOAN_ID, DISBURSED_TIME, DISBURSED_DATE, LENDER_ID, LOAN_AMOUNT, FINAL_SEGMENT_USER FROM `momovn-prod.BU_FI.BAOTU_VAYNHANH_LOAN_INFO` WHERE DISBURSED_DATE BETWEEN '2026-02-01' AND '2026-02-28' AND DISBURSED_DATE IS NOT NULL ), entry_ranked AS ( SELECT e.AGENT_ID, e.EVENT_TIME, e.ACCESSED_SOURCE, d.LOAN_ID, d.DISBURSED_TIME, d.LENDER_ID, d.LOAN_AMOUNT, d.FINAL_SEGMENT_USER, ROW_NUMBER() OVER (PARTITION BY d.LOAN_ID ORDER BY e.EVENT_TIME DESC) AS rn FROM disbursed_feb d JOIN `momovn-prod.BU_FI.BAOTU_VAYNHANH_ENTRY_POINT` e ON d.AGENT_ID = e.AGENT_ID AND e.EVENT_TIME < d.DISBURSED_TIME AND e.ETL_DATE >= '2026-01-01' ) SELECT ACCESSED_SOURCE, COUNT(*) AS loan_count, COUNT(DISTINCT AGENT_ID) AS unique_users, ROUND(SUM(LOAN_AMOUNT)/1e9,1) AS total_amount_bn, ROUND(AVG(LOAN_AMOUNT)/1e6,1) AS avg_loan_mm, ROUND(100.0*COUNT(*)/SUM(COUNT(*)) OVER(),1) AS pct FROM entry_ranked WHERE rn=1 GROUP BY ACCESSED_SOURCE ORDER BY loan_count DESC | I3: Top 3: tabbar_home 66.6% (79,780 loans), app_all_service_top 12.8% (15,374), financial_hub 5.8% (6,999). Top 4 sources = 90.4% total disbursements. | J3: 80 | K3: eval | L3: DA-SQL Agent | N3: VAYNHANH
A4: Q3 | B4: Tinh last touchpoint ma user giai ngan Vay Nhanh thang 2 chia theo final segment user | C4: Window + Complex | D4: Complex | E4: momovn-prod.BU_FI.BAOTU_VAYNHANH_LOAN_INFO, momovn-prod.BU_FI.BAOTU_VAYNHANH_ENTRY_POINT | F4: AGENT_ID, LOAN_ID, DISBURSED_TIME, DISBURSED_DATE, LOAN_AMOUNT, FINAL_SEGMENT_USER, ACCESSED_SOURCE, EVENT_TIME, ETL_DATE | G4: Last touchpoint = ENTRY_POINT row with max EVENT_TIME before DISBURSED_TIME, matched by AGENT_ID. Breakdown by FINAL_SEGMENT_USER (NEWLOAN, RELOAN, REPEATED, FM_MERCHANT_NEW, FM_MERCHANT_REPEATED, FM_STUDENT_NEW). ETL_DATE >= 2026-01-01 to limit scan. HAVING COUNT(*) >= 10 to filter noise. | H4: WITH disbursed_feb AS (SELECT AGENT_ID, LOAN_ID, DISBURSED_TIME, LOAN_AMOUNT, FINAL_SEGMENT_USER FROM `momovn-prod.BU_FI.BAOTU_VAYNHANH_LOAN_INFO` WHERE DISBURSED_DATE BETWEEN '2026-02-01' AND '2026-02-28' AND DISBURSED_DATE IS NOT NULL), entry_ranked AS (SELECT e.AGENT_ID, e.ACCESSED_SOURCE, d.LOAN_ID, d.LOAN_AMOUNT, d.FINAL_SEGMENT_USER, ROW_NUMBER() OVER (PARTITION BY d.LOAN_ID ORDER BY e.EVENT_TIME DESC) AS rn FROM disbursed_feb d JOIN `momovn-prod.BU_FI.BAOTU_VAYNHANH_ENTRY_POINT` e ON d.AGENT_ID = e.AGENT_ID AND e.EVENT_TIME < d.DISBURSED_TIME AND e.ETL_DATE >= '2026-01-01') SELECT FINAL_SEGMENT_USER, ACCESSED_SOURCE, COUNT(*) AS loans, COUNT(DISTINCT AGENT_ID) AS users, ROUND(SUM(LOAN_AMOUNT)/1e9,2) AS amount_bn, ROUND(AVG(LOAN_AMOUNT)/1e6,1) AS avg_mm, ROUND(100.0*COUNT(*)/SUM(COUNT(*)) OVER(PARTITION BY FINAL_SEGMENT_USER),1) AS pct_within_segment FROM entry_ranked WHERE rn=1 GROUP BY FINAL_SEGMENT_USER, ACCESSED_SOURCE HAVING COUNT(*)>=10 ORDER BY FINAL_SEGMENT_USER, loans DESC | I4: RELOAN: tabbar_home 69.7%, app_all_service 11.6%, search 5.1%. NEWLOAN: tabbar_home 61.6%, app_all_service 16.0%, financial_hub 10.6%. REPEATED: tabbar_home 64.3%, collection channels 5.9%. RELOAN depends more on Home; NEWLOAN explores via Financial Hub; Collection channels almost exclusively RELOAN+REPEATED. | J4: 80 | K4: eval | L4: DA-SQL Agent | M4: 2026-03-11 | N4: VAYNHANH
A5: Q4 | B5: So sanh so lan access va so ngay access truoc giai ngan giua NEWLOAN, RELOAN, REPEATED? | C5: JOIN | D5: Moderate | E5: momovn-prod.BU_FI.BAOTU_VAYNHANH_LOAN_INFO, momovn-prod.BU_FI.BAOTU_VAYNHANH_ENTRY_POINT | F5: AGENT_ID, LOAN_ID, DISBURSED_TIME, DISBURSED_DATE, FINAL_SEGMENT_USER, EVENT_TIME | G5: Count accesses + distinct days within 30d before disbursement per loan. Use APPROX_QUANTILES for median. Filter FINAL_SEGMENT_USER IN (NEWLOAN, RELOAN, REPEATED). | H5: WITH disbursed_feb AS (SELECT AGENT_ID, LOAN_ID, DISBURSED_TIME, FINAL_SEGMENT_USER FROM `momovn-prod.BU_FI.BAOTU_VAYNHANH_LOAN_INFO` WHERE DISBURSED_DATE BETWEEN '2026-02-01' AND '2026-02-28' AND DISBURSED_DATE IS NOT NULL AND FINAL_SEGMENT_USER IN ('NEWLOAN','RELOAN','REPEATED')), access_counts AS (SELECT d.LOAN_ID, d.FINAL_SEGMENT_USER, COUNT(*) AS access_count, COUNT(DISTINCT DATE(e.EVENT_TIME)) AS access_days FROM disbursed_feb d JOIN `momovn-prod.BU_FI.BAOTU_VAYNHANH_ENTRY_POINT` e ON d.AGENT_ID=e.AGENT_ID AND e.EVENT_TIME<d.DISBURSED_TIME AND e.EVENT_TIME>=TIMESTAMP_SUB(d.DISBURSED_TIME, INTERVAL 30 DAY) GROUP BY d.LOAN_ID, d.FINAL_SEGMENT_USER) SELECT FINAL_SEGMENT_USER, COUNT(*) AS loans, ROUND(AVG(access_count),1) AS avg_accesses, ROUND(APPROX_QUANTILES(access_count,100)[OFFSET(50)],0) AS median_accesses, ROUND(AVG(access_days),1) AS avg_distinct_days, ROUND(APPROX_QUANTILES(access_days,100)[OFFSET(50)],0) AS median_days FROM access_counts GROUP BY FINAL_SEGMENT_USER ORDER BY loans DESC | I5: RELOAN: median 10 accesses / 5 days. NEWLOAN: median 4 accesses / 2 days. REPEATED: median 9 / 4 days. New users decide fast (2 days), reloan users browse more (5 days). | J5: 3 | K5: eval | L5: DA-SQL Agent | M5: 2026-03-11 | N5: VAYNHANH
A6: Q5 | B6: Cohort liquidation theo thang: ty le reloan trong 30/60/90 ngay sau khi tat toan? | C6: Multi-step | D6: Moderate | E6: momovn-prod.BU_FI.BAOTU_VAYNHANH_LOAN_INFO | F6: AGENT_ID, LOAN_ID, LIQUIDATED_DATE, DISBURSED_DATE, LOAN_AMOUNT | G6: Liquidated = LIQUIDATED_DATE IS NOT NULL (NEVER use STATUS). Self-join: find next DISBURSED_DATE > LIQUIDATED_DATE within 90 days. ROW_NUMBER to get first reloan only. LEFT JOIN to keep non-reloans. Jan/Feb 2026 cohorts immature (not enough time for 60d/90d window). | H6: WITH liquidations AS (SELECT AGENT_ID, LOAN_ID AS liq_loan_id, LIQUIDATED_DATE, LENDER_ID AS liq_lender, LOAN_AMOUNT AS liq_amount, FORMAT_DATE('%Y-%m', LIQUIDATED_DATE) AS liq_month FROM `momovn-prod.BU_FI.BAOTU_VAYNHANH_LOAN_INFO` WHERE LIQUIDATED_DATE IS NOT NULL AND LIQUIDATED_DATE BETWEEN '2025-07-01' AND '2026-02-28'), next_loan AS (SELECT l.*, n.LOAN_ID AS reloan_id, n.DISBURSED_DATE AS reloan_date, n.LOAN_AMOUNT AS reloan_amount, DATE_DIFF(n.DISBURSED_DATE, l.LIQUIDATED_DATE, DAY) AS days_to_reloan, ROW_NUMBER() OVER (PARTITION BY l.AGENT_ID, l.liq_loan_id ORDER BY n.DISBURSED_DATE) AS rn FROM liquidations l LEFT JOIN `momovn-prod.BU_FI.BAOTU_VAYNHANH_LOAN_INFO` n ON l.AGENT_ID=n.AGENT_ID AND n.DISBURSED_DATE>l.LIQUIDATED_DATE AND n.DISBURSED_DATE<=DATE_ADD(l.LIQUIDATED_DATE, INTERVAL 90 DAY) AND n.DISBURSED_DATE IS NOT NULL) SELECT liq_month, COUNT(DISTINCT CONCAT(AGENT_ID, liq_loan_id)) AS total_liquidations, COUNTIF(rn=1 AND days_to_reloan<=30) AS reloan_30d, COUNTIF(rn=1 AND days_to_reloan<=60) AS reloan_60d, COUNTIF(rn=1 AND days_to_reloan<=90) AS reloan_90d, ROUND(100.0*COUNTIF(rn=1 AND days_to_reloan<=30)/COUNT(DISTINCT CONCAT(AGENT_ID, liq_loan_id)),1) AS rate_30d, ROUND(100.0*COUNTIF(rn=1 AND days_to_reloan<=60)/COUNT(DISTINCT CONCAT(AGENT_ID, liq_loan_id)),1) AS rate_60d, ROUND(100.0*COUNTIF(rn=1 AND days_to_reloan<=90)/COUNT(DISTINCT CONCAT(AGENT_ID, liq_loan_id)),1) AS rate_90d FROM next_loan WHERE rn=1 OR rn IS NULL GROUP BY liq_month ORDER BY liq_month | I6: Mature cohorts (Jul-Nov 2025): 90d reloan rate stable 58.7-62.1%. 30d rate peaked Oct at 47.9%. Feb 2026 immature at 39.3% (30d only). ~60% users reloan within 90 days of paying off. | J6: 8 | K6: eval | L6: DA-SQL Agent | M6: 2026-03-11 | N6: VAYNHANH
A7: Q6 | B7: Ti le duoc duyet (disburse/submit) chia theo segment, lender, credit score range, thang (Jul 2025 - Feb 2026)? | C7: Subquery | D7: Moderate | E7: momovn-prod.BU_FI.BAOTU_VAYNHANH_LOAN_INFO | F7: SUBMITTED_DATE, DISBURSED_DATE, FINAL_SEGMENT_USER, LENDER_ID, MOMO_CREDIT_SCORE | G7: Submitted = SUBMITTED_DATE IS NOT NULL. Disbursed = DISBURSED_DATE IS NOT NULL. Credit score buckets: <606, 606-665, 666-690, 691-715, 716-740, 741-765, 766+. NEVER use STATUS column. | H7: WITH base AS (SELECT FORMAT_DATE('%Y-%m', SUBMITTED_DATE) AS submit_month, FINAL_SEGMENT_USER, LENDER_ID, CASE WHEN MOMO_CREDIT_SCORE < 606 THEN '01 <606' WHEN MOMO_CREDIT_SCORE BETWEEN 606 AND 665 THEN '02 606-665' WHEN MOMO_CREDIT_SCORE BETWEEN 666 AND 690 THEN '03 666-690' WHEN MOMO_CREDIT_SCORE BETWEEN 691 AND 715 THEN '04 691-715' WHEN MOMO_CREDIT_SCORE BETWEEN 716 AND 740 THEN '05 716-740' WHEN MOMO_CREDIT_SCORE BETWEEN 741 AND 765 THEN '06 741-765' WHEN MOMO_CREDIT_SCORE >= 766 THEN '07 766+' ELSE '99 NULL' END AS score_range, CASE WHEN DISBURSED_DATE IS NOT NULL THEN 1 ELSE 0 END AS is_disbursed FROM `momovn-prod.BU_FI.BAOTU_VAYNHANH_LOAN_INFO` WHERE SUBMITTED_DATE IS NOT NULL AND SUBMITTED_DATE BETWEEN '2025-07-01' AND '2026-02-28') SELECT submit_month, FINAL_SEGMENT_USER AS segment, LENDER_ID AS lender, score_range, COUNT(*) AS submitted, SUM(is_disbursed) AS disbursed, ROUND(100.0*SUM(is_disbursed)/COUNT(*),1) AS approval_pct FROM base GROUP BY submit_month, FINAL_SEGMENT_USER, LENDER_ID, score_range ORDER BY submit_month, FINAL_SEGMENT_USER, LENDER_ID, score_range | I7: Overall 65-73% by month (peak Oct 73.1%, low Feb 65.3%). RELOAN 78.4% vs NEWLOAN 58.2%. MBV 76.1% > VIET_CREDIT 71.2% > AMBER 67% > MCREDIT 64.5%. Score <606: 38.9%, 666+: 78-84%. Approval rate declining as submit volume grows. | J7: 20 | K7: eval | L7: DA-SQL Agent | M7: 2026-03-11 | N7: VAYNHANH
A8: Q7 | B8: Tong gia tri giai ngan va gia tri trung binh moi khoan Vay Nhanh thang 2/2026? | C8: Aggregation | D8: Simple | E8: momovn-prod.BU_FI.BAOTU_VAYNHANH_LOAN_INFO | F8: DISBURSED_DATE, DISBURSED_AMOUNT | G8: DISBURSED_AMOUNT = LOAN_AMOUNT in this table. Use DISBURSED_DATE for time filter. | H8: SELECT ROUND(SUM(DISBURSED_AMOUNT)/1e9,1) AS total_bn, ROUND(AVG(DISBURSED_AMOUNT)/1e6,1) AS avg_mm FROM `momovn-prod.BU_FI.BAOTU_VAYNHANH_LOAN_INFO` WHERE DISBURSED_DATE BETWEEN '2026-02-01' AND '2026-02-28' AND DISBURSED_DATE IS NOT NULL | I8: Total 2,515.2 bn VND, avg 17.6M per loan | J8: 1 | K8: eval | L8: DA-SQL Agent | M8: 2026-03-10 | N8: VAYNHANH
A9: Q8 | B9: So sanh giai ngan Vay Nhanh thang 1 va thang 2/2026? | C9: Aggregation | D9: Simple | E9: momovn-prod.BU_FI.BAOTU_VAYNHANH_LOAN_INFO | F9: DISBURSED_DATE, AGENT_ID, DISBURSED_AMOUNT | G9: Feb has fewer days + Tet holiday. MoM comparison expected to show decline. | H9: SELECT FORMAT_DATE('%Y-%m', DISBURSED_DATE) AS month, COUNT(*) AS loans, COUNT(DISTINCT AGENT_ID) AS users, ROUND(SUM(DISBURSED_AMOUNT)/1e9,1) AS amount_bn, ROUND(AVG(DISBURSED_AMOUNT)/1e6,1) AS avg_mm FROM `momovn-prod.BU_FI.BAOTU_VAYNHANH_LOAN_INFO` WHERE DISBURSED_DATE BETWEEN '2026-01-01' AND '2026-02-28' AND DISBURSED_DATE IS NOT NULL GROUP BY month ORDER BY month | I9: Jan 171,573 loans / 3,108.4bn -> Feb 143,176 loans / 2,515.2bn (-16.5% loans, -19.1% amount) | J9: 2 | K9: eval | L9: DA-SQL Agent | M9: 2026-03-10 | N9: VAYNHANH
A10: Q9 | B10: Phan bo so lan giai ngan cua user Vay Nhanh thang 2/2026? | C10: Aggregation | D10: Simple | E10: momovn-prod.BU_FI.BAOTU_VAYNHANH_LOAN_INFO | F10: DISBURSED_COUNT_TIME, DISBURSED_AMOUNT, DISBURSED_DATE | G10: DISBURSED_COUNT_TIME = ordinal loan number per user. Higher count = more experienced borrower. | H10: SELECT CASE WHEN DISBURSED_COUNT_TIME=1 THEN '1st loan' WHEN DISBURSED_COUNT_TIME=2 THEN '2nd loan' WHEN DISBURSED_COUNT_TIME=3 THEN '3rd loan' WHEN DISBURSED_COUNT_TIME BETWEEN 4 AND 5 THEN '4-5th loan' WHEN DISBURSED_COUNT_TIME BETWEEN 6 AND 10 THEN '6-10th loan' ELSE '11+ loan' END AS loan_sequence, MIN(DISBURSED_COUNT_TIME) AS sort_key, COUNT(*) AS loans, ROUND(AVG(DISBURSED_AMOUNT)/1e6,1) AS avg_mm, ROUND(100.0*COUNT(*)/SUM(COUNT(*)) OVER(),1) AS pct FROM `momovn-prod.BU_FI.BAOTU_VAYNHANH_LOAN_INFO` WHERE DISBURSED_DATE BETWEEN '2026-02-01' AND '2026-02-28' AND DISBURSED_DATE IS NOT NULL GROUP BY loan_sequence ORDER BY sort_key | I10: 1st loan 34.5% (avg 13.5M), 2nd 21.7% (avg 17.8M), 3rd 14.3% (avg 21.3M). Avg increases with sequence. | J10: 1 | K10: eval | L10: DA-SQL Agent | M10: 2026-03-10 | N10: VAYNHANH
A11: Q10 | B11: Top 10 ly do tu choi don vay Vay Nhanh thang 2/2026? | C11: Aggregation | D11: Simple | E11: momovn-prod.BU_FI.BAOTU_VAYNHANH_LOAN_INFO | F11: REJECTED_REASON, CREATED_DATE | G11: REJECTED_REASON populated regardless of STATUS. Filter by CREATED_DATE. Top reasons: RJ_DEDUP, blacklist, bad debt. | H11: SELECT REJECTED_REASON, COUNT(*) AS cnt FROM `momovn-prod.BU_FI.BAOTU_VAYNHANH_LOAN_INFO` WHERE CREATED_DATE BETWEEN '2026-02-01' AND '2026-02-28' AND REJECTED_REASON IS NOT NULL AND REJECTED_REASON != '' GROUP BY REJECTED_REASON ORDER BY cnt DESC LIMIT 10 | I11: Top 3: RJ_DEDUP (10,135), FASTMONEY_REF_BLACKLIST (9,170), RJ_BAD_DEBT (6,893) | J11: 10 | K11: eval | L11: DA-SQL Agent | M11: 2026-03-10 | N11: VAYNHANH
A12: Q11 | B12: So luong user duy nhat giai ngan Vay Nhanh thang 2/2026 va trung binh moi user vay bao nhieu khoan? | C12: Aggregation | D12: Simple | E12: momovn-prod.BU_FI.BAOTU_VAYNHANH_LOAN_INFO | F12: AGENT_ID, DISBURSED_DATE | G12: User = AGENT_ID (not BORROWER_ID). Loans per user = total_loans / unique_users. | H12: SELECT COUNT(DISTINCT AGENT_ID) AS unique_borrowers, COUNT(*) AS total_loans, ROUND(COUNT(*)*1.0/COUNT(DISTINCT AGENT_ID),2) AS loans_per_user FROM `momovn-prod.BU_FI.BAOTU_VAYNHANH_LOAN_INFO` WHERE DISBURSED_DATE BETWEEN '2026-02-01' AND '2026-02-28' AND DISBURSED_DATE IS NOT NULL | I12: 126,248 unique users, 143,176 loans, 1.13 loans/user | J12: 1 | K12: eval | L12: DA-SQL Agent | M12: 2026-03-10 | N12: VAYNHANH
A13: Q12 | B13: Phan bo ky han (tenor) cac khoan vay Vay Nhanh thang 2/2026? | C13: Aggregation | D13: Simple | E13: momovn-prod.BU_FI.BAOTU_VAYNHANH_LOAN_INFO | F13: TENOR, DISBURSED_AMOUNT, DISBURSED_DATE | G13: Tenor in months. Short-term (1-6 months) dominates. Longer tenor = higher avg loan. | H13: SELECT CAST(TENOR AS INT64) AS tenor_months, COUNT(*) AS loans, ROUND(AVG(DISBURSED_AMOUNT)/1e6,1) AS avg_mm, ROUND(100.0*COUNT(*)/SUM(COUNT(*)) OVER(),1) AS pct FROM `momovn-prod.BU_FI.BAOTU_VAYNHANH_LOAN_INFO` WHERE DISBURSED_DATE BETWEEN '2026-02-01' AND '2026-02-28' AND DISBURSED_DATE IS NOT NULL GROUP BY tenor_months ORDER BY loans DESC | I13: 6-month tenor dominates (28.7%, avg 7.2M), then 9-month (15.5%), 12-month (13.5%). 36-month avg 62M. | J13: 1 | K13: eval | L13: DA-SQL Agent | M13: 2026-03-10 | N13: VAYNHANH
A14: Q13 | B14: Giai ngan Vay Nhanh theo ngay trong tuan thang 2/2026? | C14: Aggregation | D14: Simple | E14: momovn-prod.BU_FI.BAOTU_VAYNHANH_LOAN_INFO | F14: DISBURSED_DATE, DISBURSED_AMOUNT | G14: Use EXTRACT(DAYOFWEEK) or FORMAT_DATE('%A'). Weekend typically lower. | H14: SELECT FORMAT_DATE('%A', DISBURSED_DATE) AS day_of_week, EXTRACT(DAYOFWEEK FROM DISBURSED_DATE) AS dow_num, COUNT(*) AS loans, ROUND(SUM(DISBURSED_AMOUNT)/1e9,2) AS amount_bn, ROUND(AVG(DISBURSED_AMOUNT)/1e6,1) AS avg_mm FROM `momovn-prod.BU_FI.BAOTU_VAYNHANH_LOAN_INFO` WHERE DISBURSED_DATE BETWEEN '2026-02-01' AND '2026-02-28' AND DISBURSED_DATE IS NOT NULL GROUP BY day_of_week, dow_num ORDER BY dow_num | I14: 7 rows. Need to run to get exact numbers. | J14: 1 | K14: eval | L14: DA-SQL Agent | M14: 2026-03-10 | N14: VAYNHANH
A15: Q14 | B15: Thoi gian trung binh tu submit den giai ngan Vay Nhanh thang 2/2026 theo lender? | C15: Aggregation | D15: Moderate | E15: momovn-prod.BU_FI.BAOTU_VAYNHANH_LOAN_INFO | F15: LENDER_ID, SUBMITTED_TIME, DISBURSED_TIME, DISBURSED_DATE | G15: Use TIMESTAMP_DIFF(DISBURSED_TIME, SUBMITTED_TIME, MINUTE). SUBMITTED_TIME must not be null. | H15: SELECT LENDER_ID, COUNT(*) AS loans, ROUND(AVG(TIMESTAMP_DIFF(DISBURSED_TIME, SUBMITTED_TIME, MINUTE)),1) AS avg_minutes, ROUND(APPROX_QUANTILES(TIMESTAMP_DIFF(DISBURSED_TIME, SUBMITTED_TIME, MINUTE),100)[OFFSET(50)],1) AS median_minutes FROM `momovn-prod.BU_FI.BAOTU_VAYNHANH_LOAN_INFO` WHERE DISBURSED_DATE BETWEEN '2026-02-01' AND '2026-02-28' AND DISBURSED_DATE IS NOT NULL AND SUBMITTED_TIME IS NOT NULL GROUP BY LENDER_ID ORDER BY loans DESC | I15: VIET_CREDIT avg 2.1min (median 2), MCREDIT avg 6.3min (median 0), MBV avg 2.3min (median 1), AMBER avg 2.4min (median 2) | J15: 1 | K15: eval | L15: DA-SQL Agent | M15: 2026-03-10 | N15: VAYNHANH
A16: Q15 | B16: Tan suat truy cap theo ngay truoc giai ngan (day 0 den day -30) cua user Vay Nhanh thang 2? | C16: JOIN | D16: Moderate | E16: momovn-prod.BU_FI.BAOTU_VAYNHANH_LOAN_INFO, momovn-prod.BU_FI.BAOTU_VAYNHANH_ENTRY_POINT | F16: AGENT_ID, LOAN_ID, DISBURSED_TIME, DISBURSED_DATE, EVENT_TIME | G16: TIMESTAMP_DIFF(DISBURSED_TIME, EVENT_TIME, DAY) = days before disbursement. Day 0 = same day as disbursement. Join within 30-day window. | H16: WITH disbursed_feb AS (SELECT AGENT_ID, LOAN_ID, DISBURSED_TIME FROM `momovn-prod.BU_FI.BAOTU_VAYNHANH_LOAN_INFO` WHERE DISBURSED_DATE BETWEEN '2026-02-01' AND '2026-02-28' AND DISBURSED_DATE IS NOT NULL) SELECT TIMESTAMP_DIFF(d.DISBURSED_TIME, e.EVENT_TIME, DAY) AS days_before_disbursement, COUNT(*) AS total_accesses, COUNT(DISTINCT d.LOAN_ID) AS unique_loans FROM disbursed_feb d JOIN `momovn-prod.BU_FI.BAOTU_VAYNHANH_ENTRY_POINT` e ON d.AGENT_ID=e.AGENT_ID AND e.EVENT_TIME<d.DISBURSED_TIME AND e.EVENT_TIME>=TIMESTAMP_SUB(d.DISBURSED_TIME, INTERVAL 30 DAY) GROUP BY days_before_disbursement ORDER BY days_before_disbursement | I16: Day 0 spike: 205K accesses (49,707 loans = 43%). Day 1: 103K (-50%). Day 7-28: plateau ~40-56K accesses/day. Pattern: sharp spike day 0-1, then long flat tail. | J16: 30 | K16: eval | L16: DA-SQL Agent | M16: 2026-03-11 | N16: VAYNHANH
A17: Q16 | B17: So sanh so lan access va so ngay access truoc giai ngan giua NEWLOAN, RELOAN, REPEATED? | C17: Subquery | D17: Complex | E17: momovn-prod.BU_FI.BAOTU_VAYNHANH_LOAN_INFO, momovn-prod.BU_FI.BAOTU_VAYNHANH_ENTRY_POINT | F17: AGENT_ID, LOAN_ID, DISBURSED_TIME, DISBURSED_DATE, FINAL_SEGMENT_USER, EVENT_TIME | G17: Count accesses + distinct days within 30d before disbursement per loan. Use APPROX_QUANTILES for median. Filter FINAL_SEGMENT_USER IN (NEWLOAN, RELOAN, REPEATED). | H17: WITH disbursed_feb AS (SELECT AGENT_ID, LOAN_ID, DISBURSED_TIME, FINAL_SEGMENT_USER FROM `momovn-prod.BU_FI.BAOTU_VAYNHANH_LOAN_INFO` WHERE DISBURSED_DATE BETWEEN '2026-02-01' AND '2026-02-28' AND DISBURSED_DATE IS NOT NULL AND FINAL_SEGMENT_USER IN ('NEWLOAN','RELOAN','REPEATED')), access_counts AS (SELECT d.LOAN_ID, d.FINAL_SEGMENT_USER, COUNT(*) AS access_count, COUNT(DISTINCT DATE(e.EVENT_TIME)) AS access_days FROM disbursed_feb d JOIN `momovn-prod.BU_FI.BAOTU_VAYNHANH_ENTRY_POINT` e ON d.AGENT_ID=e.AGENT_ID AND e.EVENT_TIME<d.DISBURSED_TIME AND e.EVENT_TIME>=TIMESTAMP_SUB(d.DISBURSED_TIME, INTERVAL 30 DAY) GROUP BY d.LOAN_ID, d.FINAL_SEGMENT_USER) SELECT FINAL_SEGMENT_USER, COUNT(*) AS loans, ROUND(AVG(access_count),1) AS avg_accesses, ROUND(APPROX_QUANTILES(access_count,100)[OFFSET(50)],0) AS median_accesses, ROUND(AVG(access_days),1) AS avg_distinct_days, ROUND(APPROX_QUANTILES(access_days,100)[OFFSET(50)],0) AS median_days FROM access_counts GROUP BY FINAL_SEGMENT_USER ORDER BY loans DESC | I17: RELOAN: median 10 accesses / 5 days. NEWLOAN: median 4 accesses / 2 days. REPEATED: median 9 / 4 days. New users decide fast (2 days), reloan users browse more (5 days). | J17: 3 | K17: eval | L17: DA-SQL Agent | M17: 2026-03-11 | N17: VAYNHANH
A18: Q17 | B18: Thoi gian trung binh tu tat toan den reloan theo thang | C18: Subquery | D18: Complex | E18: momovn-prod.BU_FI.BAOTU_VAYNHANH_LOAN_INFO | F18: AGENT_ID, LOAN_ID, LIQUIDATED_DATE, DISBURSED_DATE | G18: Self-join to find first reloan after liquidation (no time cap). Use APPROX_QUANTILES for percentiles. Recent cohorts appear faster because only near-term reloans observed (right-censoring). | H18: WITH liquidations AS (SELECT AGENT_ID, LOAN_ID AS liq_loan_id, LIQUIDATED_DATE, FORMAT_DATE('%Y-%m', LIQUIDATED_DATE) AS liq_month FROM `momovn-prod.BU_FI.BAOTU_VAYNHANH_LOAN_INFO` WHERE LIQUIDATED_DATE IS NOT NULL AND LIQUIDATED_DATE BETWEEN '2025-07-01' AND '2026-02-28'), next_loan AS (SELECT l.*, n.DISBURSED_DATE AS reloan_date, DATE_DIFF(n.DISBURSED_DATE, l.LIQUIDATED_DATE, DAY) AS days_to_reloan, ROW_NUMBER() OVER (PARTITION BY l.AGENT_ID, l.liq_loan_id ORDER BY n.DISBURSED_DATE) AS rn FROM liquidations l JOIN `momovn-prod.BU_FI.BAOTU_VAYNHANH_LOAN_INFO` n ON l.AGENT_ID=n.AGENT_ID AND n.DISBURSED_DATE>l.LIQUIDATED_DATE AND n.DISBURSED_DATE IS NOT NULL) SELECT liq_month, COUNT(*) AS reloans, ROUND(AVG(days_to_reloan),1) AS avg_days, ROUND(APPROX_QUANTILES(days_to_reloan,100)[OFFSET(25)],0) AS p25_days, ROUND(APPROX_QUANTILES(days_to_reloan,100)[OFFSET(50)],0) AS median_days, ROUND(APPROX_QUANTILES(days_to_reloan,100)[OFFSET(75)],0) AS p75_days FROM next_loan WHERE rn=1 GROUP BY liq_month ORDER BY liq_month | I18: Mature cohorts: median 9-17 days to reloan. P25 = 3-4 days (instant reloans). Oct 2025 median 10d, Dec median 9d. Users pay off and reborrow within 2 weeks typically. | J18: 8 | K18: eval | L18: DA-SQL Agent | M18: 2026-03-11 | N18: VAYNHANH
A19: Q18 | B19: So sanh traffic user khong co khoan vay giua thang 3/2026 va thang 1/2026 cung ky (1-11)? | C19: Subquery | D19: Complex | E19: momovn-prod.BU_FI.BAOTU_VAYNHANH_LOAN_INFO, momovn-prod.BU_FI.BAOTU_VAYNHANH_ENTRY_POINT | F19: AGENT_ID, DISBURSED_DATE, LIQUIDATED_DATE, ETL_DATE, ACCESSED_SOURCE | G19: No-loan users = LEFT JOIN loan_info WHERE active loan IS NULL. Compare same period (1-11) for fairness. Active loan at time = disbursed before period end AND (not liquidated OR liquidated after period start). | H19: WITH active_loans_jan AS (SELECT DISTINCT AGENT_ID FROM `momovn-prod.BU_FI.BAOTU_VAYNHANH_LOAN_INFO` WHERE DISBURSED_DATE IS NOT NULL AND (LIQUIDATED_DATE IS NULL OR LIQUIDATED_DATE>='2026-01-01') AND DISBURSED_DATE<'2026-01-12'), active_loans_mar AS (SELECT DISTINCT AGENT_ID FROM `momovn-prod.BU_FI.BAOTU_VAYNHANH_LOAN_INFO` WHERE DISBURSED_DATE IS NOT NULL AND (LIQUIDATED_DATE IS NULL OR LIQUIDATED_DATE>='2026-03-01') AND DISBURSED_DATE<'2026-03-12'), jan_traffic AS (SELECT e.ACCESSED_SOURCE, COUNT(*) AS sessions, COUNT(DISTINCT e.AGENT_ID) AS users FROM `momovn-prod.BU_FI.BAOTU_VAYNHANH_ENTRY_POINT` e LEFT JOIN active_loans_jan a ON e.AGENT_ID=a.AGENT_ID WHERE e.ETL_DATE BETWEEN '2026-01-01' AND '2026-01-11' AND a.AGENT_ID IS NULL GROUP BY e.ACCESSED_SOURCE), mar_traffic AS (SELECT e.ACCESSED_SOURCE, COUNT(*) AS sessions, COUNT(DISTINCT e.AGENT_ID) AS users FROM `momovn-prod.BU_FI.BAOTU_VAYNHANH_ENTRY_POINT` e LEFT JOIN active_loans_mar a ON e.AGENT_ID=a.AGENT_ID WHERE e.ETL_DATE BETWEEN '2026-03-01' AND '2026-03-11' AND a.AGENT_ID IS NULL GROUP BY e.ACCESSED_SOURCE) SELECT COALESCE(m.ACCESSED_SOURCE,j.ACCESSED_SOURCE) AS source, IFNULL(j.users,0) AS jan_users, IFNULL(j.sessions,0) AS jan_sessions, IFNULL(m.users,0) AS mar_users, IFNULL(m.sessions,0) AS mar_sessions, IFNULL(m.users,0)-IFNULL(j.users,0) AS user_diff, ROUND(100.0*SAFE_DIVIDE(IFNULL(m.users,0)-IFNULL(j.users,0),IFNULL(j.users,0)),1) AS user_growth_pct FROM mar_traffic m FULL OUTER JOIN jan_traffic j ON m.ACCESSED_SOURCE=j.ACCESSED_SOURCE ORDER BY IFNULL(m.users,0)+IFNULL(j.users,0) DESC | I19: Mar vs Jan (1-11): 550K vs 615K users (-10.5%). Sessions 1.53M vs 1.97M (-22.4%). Sessions/user 2.8 vs 3.2. tabbar_home -56K (-16%), financial_hub -44K (-27%), momo_passport -28K (-68%). Only app_all_service_top grew +15K (+11%). | J19: 50 | K19: eval | L19: DA-SQL Agent | M19: 2026-03-11 | N19: VAYNHANH
A20: Q19 | B20: DPD30 cac khoan vay theo vintage va lender (chi dung LOAN_INFO, khong dung bang vintage)? | C20: Ambiguous | D20: Ambiguous | E20: momovn-prod.BU_FI.BAOTU_VAYNHANH_LOAN_INFO | F20: DISBURSED_DATE, LIQUIDATED_DATE, FIRST_DUE_DATE, TENOR, LENDER_ID, LOAN_AMOUNT | G20: LOAN_INFO khong co du lieu thanh toan tung ky. Chi biet loan da liquidated hay chua | J20: 1 | K20: eval | L20: DA-SQL Agent | M20: 2026-03-11 | N20: VAYNHANH
A22: TTT001 | B22: AUM tháng 1 bao nhiêu? | C22: Aggregation | D22: Simple | E22: mart_ttt_daily_user_record | F22: BALANCE, GRASS_DATE | G22: AUM = SUM(BALANCE) tại ngày cuối tháng (snapshot), KHÔNG phải SUM across all days. Nếu SUM cả tháng → inflate ~30x. Không filter MAU/MFU vì churn accounts vẫn có balance. Câu hỏi không nói rõ năm nào → LLM phải infer 2026. Không nói rõ breakdown Individual vs Money Pool → LLM có thể miss hoặc tự ý breakdown. | H22: SELECT SUM(BALANCE) AS total_aum FROM `momovn-prod.BU_FI.mart_ttt_daily_user_record` WHERE GRASS_DATE = '2026-01-31' | I22: 1 row, total_aum ~11.57T VND | J22: 1 | K22: eval | L22: DA Team (AI-assisted) | M22: 46091 | N22: TTT
A23: TTT002 | B23: Có bao nhiêu người đang dùng TTT vậy? | C23: Ambiguous | D23: Ambiguous | E23: mart_ttt_daily_user_record | F23: USER_ID, MAU_TYPE, GRASS_DATE | G23: Đang dùng = MAU hay MFU? Không nói tháng nào. Agent tốt nên hỏi lại: "Ý anh/chị là người mở app (MAU ~3.5M) hay người thực sự có tiền (MFU ~1.7M)?". USER_ID cần REGEXP_EXTRACT vì mp_ prefix gây double-count. Nếu agent tự đoán mà không clarify → penalty. | H23: -- Agent nên hỏi lại. Nếu buộc phải trả lời, MAU là default hợp lý: SELECT COUNT(DISTINCT CAST(REGEXP_EXTRACT(USER_ID, r'\d+') AS STRING)) AS total_mau FROM `momovn-prod.BU_FI.mart_ttt_daily_user_record` WHERE GRASS_DATE BETWEEN '2026-02-01' AND '2026-02-28' AND MAU_TYPE != '0.Churn' | I23: 1 row, ~3.4-3.5M (nếu MAU) hoặc ~1.67M (nếu MFU) | J23: 1 | K23: eval | L23: DA Team (AI-assisted) | M23: 46091 | N23: TTT
A24: TTT003 | B24: Tháng rồi người ta gửi vô TTT tổng bao nhiêu tiền? | C24: Aggregation | D24: Moderate | E24: mart_ttt_daily_user_record | F24: cashin_gmv, cashin_p2p_gmv, cashin_va_gmv, cashin_ai_gmv, cashin_stock_gmv, cashin_payout_gmv, cashin_mp_gmv, GRASS_DATE | G24: Tháng rồi = tháng trước (agent phải infer). Total cashin = SUM tất cả 7 sub-channels, không chỉ cashin_gmv (~50% total). COALESCE(col, 0) vì NULL. "Gửi vô" = cashin, không phải balance. LLM yếu thường chỉ dùng cashin_gmv. | H24: SELECT SUM( COALESCE(cashin_gmv, 0) + COALESCE(cashin_p2p_gmv, 0) + COALESCE(cashin_va_gmv, 0) + COALESCE(cashin_ai_gmv, 0) + COALESCE(cashin_stock_gmv, 0) + COALESCE(cashin_payout_gmv, 0) + COALESCE(cashin_mp_gmv, 0) ) AS total_cashin FROM `momovn-prod.BU_FI.mart_ttt_daily_user_record` WHERE GRASS_DATE BETWEEN '2026-02-01' AND '2026-02-28' | I24: 1 row, total cashin cả tháng | J24: 1 | K24: eval | L24: DA Team (AI-assisted) | M24: 46091 | N24: TTT
A25: TTT004 | B25: MoMo đang trả lãi cho TTT mỗi tháng bao nhiêu vậy? Có đáng lo không? | C25: Aggregation | D25: Simple | E25: mart_ttt_daily_user_record | F25: INTEREST, GRASS_DATE | G25: Column tên `INTEREST` (KHÔNG phải `interest_gmv` — column name sai phổ biến nhất). Interest = chi phí MoMo trả cho user/ngày, SUM across tháng. "Có đáng lo không" = phần business interpretation, agent không cần SQL cho phần này. LLM có thể dùng sai column name → query fail. | H25: SELECT SUM(INTEREST) AS total_interest_paid FROM `momovn-prod.BU_FI.mart_ttt_daily_user_record` WHERE GRASS_DATE BETWEEN '2026-02-01' AND '2026-02-28' | I25: 1 row, ~37-38B VND/month | J25: 1 | K25: eval | L25: DA Team (AI-assisted) | M25: 46091 | N25: TTT
A26: TTT005 | B26: Tháng 1 so với tháng 2 thì TTT đang lên hay xuống? | C26: Multi-step | D26: Ambiguous | E26: mart_ttt_daily_user_record | F26: BALANCE, USER_ID, MAU_TYPE, INTEREST, cashin sub-channels, GRASS_DATE | G26: Câu hỏi cực kỳ vague — "lên hay xuống" theo metric nào? AUM? MAU? Cashin? Agent tốt nên hỏi lại hoặc decompose thành multiple metrics. Mỗi metric có date logic khác nhau (AUM = snapshot, MAU = full range, cashin = SUM range). Nếu agent chỉ trả 1 metric → incomplete. | H26: -- Cần multiple queries. Minimum viable: AUM + MAU for 2 months WITH jan_stats AS ( SELECT SUM(CASE WHEN GRASS_DATE = '2026-01-31' THEN BALANCE ELSE 0 END) AS aum, COUNT(DISTINCT CASE WHEN MAU_TYPE != '0.Churn' THEN CAST(REGEXP_EXTRACT(USER_ID, r'\d+') AS STRING) END) AS mau FROM `momovn-prod.BU_FI.mart_ttt_daily_user_record` WHERE GRASS_DATE BETWEEN '2026-01-01' AND '2026-01-31' ), feb_stats AS ( SELECT SUM(CASE WHEN GRASS_DATE = '2026-02-28' THEN BALANCE ELSE 0 END) AS aum, COUNT(DISTINCT CASE WHEN MAU_TYPE != '0.Churn' THEN CAST(REGEXP_EXTRACT(USER_ID, r'\d+') AS STRING) END) AS mau FROM `momovn-prod.BU_FI.mart_ttt_daily_user_record` WHERE GRASS_DATE BETWEEN '2026-02-01' AND '2026-02-28' ) SELECT 'Jan' AS month, aum, mau FROM jan_stats UNION ALL SELECT 'Feb', aum, mau FROM feb_stats | I26: 2 rows: Jan vs Feb cho AUM + MAU | J26: 2 | K26: eval | L26: DA Team (AI-assisted) | M26: 46091 | N26: TTT
A27: TTT006 | B27: Vùng nào đang dùng TTT nhiều nhất? Top 5 cho t | C27: Ranking + Filter | D27: Moderate | E27: mart_ttt_daily_user_record | F27: REGION, USER_ID, MAU_TYPE, GRASS_DATE | G27: Dùng nhiều nhất = MAU count. Cần filter MAU_TYPE != '0.Churn'. REGEXP_EXTRACT cho USER_ID dedup. REGION có thể NULL → COALESCE. LIMIT 5. Không nói rõ tháng → agent phải infer tháng gần nhất. | H27: SELECT COALESCE(REGION, 'Unknown') AS region, COUNT(DISTINCT CAST(REGEXP_EXTRACT(USER_ID, r'\d+') AS STRING)) AS active_users FROM `momovn-prod.BU_FI.mart_ttt_daily_user_record` WHERE GRASS_DATE BETWEEN '2026-02-01' AND '2026-02-28' AND MAU_TYPE != '0.Churn' GROUP BY COALESCE(REGION, 'Unknown') ORDER BY active_users DESC LIMIT 5 | I27: 5 rows — top 5 regions | J27: 5 | K27: eval | L27: DA Team (AI-assisted) | M27: 46091 | N27: TTT
A28: TTT007 | B28: Tiền rút ra nhiều hơn tiền gửi vào không? Tháng 2 | C28: Multi-step | D28: Complex | E28: mart_ttt_daily_user_record | F28: Tất cả 7 cashin + 7 cashout sub-channels, GRASS_DATE | G28: Net cash = Total Cashin - Total Cashout. Phải SUM đủ 7+7 sub-channels, mỗi cái COALESCE. Câu hỏi hỏi yes/no nhưng SQL cần tính cả 2 phía. Nếu chỉ dùng cashin_gmv và cashout_gmv → miss ~50% flow, có thể sai direction. | H28: SELECT SUM( COALESCE(cashin_gmv, 0) + COALESCE(cashin_p2p_gmv, 0) + COALESCE(cashin_va_gmv, 0) + COALESCE(cashin_ai_gmv, 0) + COALESCE(cashin_stock_gmv, 0) + COALESCE(cashin_payout_gmv, 0) + COALESCE(cashin_mp_gmv, 0) ) AS total_cashin, SUM( COALESCE(cashout_gmv, 0) + COALESCE(cashout_napas_gmv, 0) + COALESCE(cashout_p2p_gmv, 0) + COALESCE(cashout_payment_gmv, 0) + COALESCE(cashout_stock_gmv, 0) + COALESCE(cashout_mp_gmv, 0) + COALESCE(cashout_payment_mp_gmv, 0) ) AS total_cashout FROM `momovn-prod.BU_FI.mart_ttt_daily_user_record` WHERE GRASS_DATE BETWEEN '2026-02-01' AND '2026-02-28' | I28: 1 row: total_cashin vs total_cashout, net cash = cashin - cashout | J28: 1 | K28: eval | L28: DA Team (AI-assisted) | M28: 46091 | N28: TTT
A29: TTT008 | B29: Nhóm tuổi nào gửi tiết kiệm TTT nhiều nhất? | C29: Aggregation | D29: Moderate | E29: mart_ttt_daily_user_record | F29: AGE_GROUP, BALANCE, GRASS_DATE | G29: Gửi tiết kiệm nhiều nhất có thể hiểu là total AUM hoặc total cashin — ambiguous nhẹ. AGE_GROUP format: '1.Below 22', '2.23-27', '3.28-35', '4.36-50', '5.Above 50'. Nên dùng AUM snapshot cuối tháng (default interpretation). ORDER BY DESC, không cần LIMIT (chỉ ~5-6 groups). | H29: SELECT AGE_GROUP, SUM(BALANCE) AS total_aum, COUNT(DISTINCT CAST(REGEXP_EXTRACT(USER_ID, r'\d+') AS STRING)) AS user_count FROM `momovn-prod.BU_FI.mart_ttt_daily_user_record` WHERE GRASS_DATE = '2026-01-31' AND BALANCE > 0 GROUP BY AGE_GROUP ORDER BY total_aum DESC | I29: ~5-6 rows, sorted by AUM desc | J29: 46148 | K29: eval | L29: DA Team (AI-assisted) | M29: 46091 | N29: TTT
A30: TTT009 | B30: Bao nhiêu % user TTT đang dùng Túi+? | C30: Conditional Logic | D30: Moderate | E30: mart_ttt_daily_user_record | F30: PLUS_TYPE, USER_ID, MAU_TYPE, GRASS_DATE | G30: Túi+ users = PLUS_TYPE NOT IN ('0.Churn', 'None') AND PLUS_TYPE IS NOT NULL. Base = MAU (MAU_TYPE != '0.Churn'). REGEXP_EXTRACT cả tử lẫn mẫu. LLM thường không biết filter logic của PLUS_TYPE — dễ include churn Túi+ hoặc 'None' value. | H30: SELECT COUNT(DISTINCT CASE WHEN PLUS_TYPE NOT IN ('0.Churn', 'None') AND PLUS_TYPE IS NOT NULL THEN CAST(REGEXP_EXTRACT(USER_ID, r'\d+') AS STRING) END) * 100.0 / NULLIF(COUNT(DISTINCT CASE WHEN MAU_TYPE != '0.Churn' THEN CAST(REGEXP_EXTRACT(USER_ID, r'\d+') AS STRING) END), 0) AS tui_plus_pct FROM `momovn-prod.BU_FI.mart_ttt_daily_user_record` WHERE GRASS_DATE BETWEEN '2026-01-01' AND '2026-01-31' | I30: 1 row, tui_plus_pct (%) | J30: 1 | K30: eval | L30: DA Team (AI-assisted) | M30: 46091 | N30: TTT
A31: TTT010 | B31: Người dùng rút tiền từ TTT chủ yếu qua kênh nào? | C31: Ranking + Filter | D31: Moderate | E31: mart_ttt_daily_user_record | F31: cashout_gmv, cashout_napas_gmv, cashout_p2p_gmv, cashout_payment_gmv, cashout_stock_gmv, cashout_mp_gmv, cashout_payment_mp_gmv, GRASS_DATE | G31: Cần breakdown 7 cashout sub-channels để so sánh. "Chủ yếu" = channel có GMV cao nhất. LLM thường chỉ biết cashout_gmv, không biết 6 kênh còn lại. Format output nên UNPIVOT hoặc liệt kê từng kênh. COALESCE. | H31: SELECT 'basic' AS channel, SUM(COALESCE(cashout_gmv, 0)) AS gmv FROM `momovn-prod.BU_FI.mart_ttt_daily_user_record` WHERE GRASS_DATE BETWEEN '2026-02-01' AND '2026-02-28' UNION ALL SELECT 'napas', SUM(COALESCE(cashout_napas_gmv, 0)) FROM `momovn-prod.BU_FI.mart_ttt_daily_user_record` WHERE GRASS_DATE BETWEEN '2026-02-01' AND '2026-02-28' UNION ALL SELECT 'p2p', SUM(COALESCE(cashout_p2p_gmv, 0)) FROM `momovn-prod.BU_FI.mart_ttt_daily_user_record` WHERE GRASS_DATE BETWEEN '2026-02-01' AND '2026-02-28' UNION ALL SELECT 'payment', SUM(COALESCE(cashout_payment_gmv, 0)) FROM `momovn-prod.BU_FI.mart_ttt_daily_user_record` WHERE GRASS_DATE BETWEEN '2026-02-01' AND '2026-02-28' UNION ALL SELECT 'stock', SUM(COALESCE(cashout_stock_gmv, 0)) FROM `momovn-prod.BU_FI.mart_ttt_daily_user_record` WHERE GRASS_DATE BETWEEN '2026-02-01' AND '2026-02-28' UNION ALL SELECT 'money_pool', SUM(COALESCE(cashout_mp_gmv, 0)) FROM `momovn-prod.BU_FI.mart_ttt_daily_user_record` WHERE GRASS_DATE BETWEEN '2026-02-01' AND '2026-02-28' UNION ALL SELECT 'payment_mp', SUM(COALESCE(cashout_payment_mp_gmv, 0)) FROM `momovn-prod.BU_FI.mart_ttt_daily_user_record` WHERE GRASS_DATE BETWEEN '2026-02-01' AND '2026-02-28' ORDER BY gmv DESC | I31: 7 rows, sorted by GMV desc — top channel likely p2p or payment | J31: 7 | K31: eval | L31: DA Team (AI-assisted) | M31: 46091 | N31: TTT
A32: TTT011 | B32: User mới tháng này so tháng trước tăng hay giảm? Giảm bao nhiêu? | C32: Date/Time | D32: Moderate | E32: mart_ttt_daily_user_record | F32: USER_ID, MAU_TYPE, GRASS_DATE | G32: User mới = MAU_TYPE = '1.New' (KHÔNG phải != '0.Churn'). "Tháng này" vs "tháng trước" → agent phải infer relative dates. Cần REGEXP_EXTRACT. Dùng DATE_TRUNC(GRASS_DATE, MONTH) — KHÔNG dùng GRASS_MONTH (không tồn tại). LLM hay nhầm MAU_TYPE != '0.Churn' (= tất cả active, gồm retain + reactive) vs = '1.New' (chỉ new). | H32: WITH monthly_new AS ( SELECT DATE_TRUNC(GRASS_DATE, MONTH) AS month, COUNT(DISTINCT CAST(REGEXP_EXTRACT(USER_ID, r'\d+') AS STRING)) AS new_users FROM `momovn-prod.BU_FI.mart_ttt_daily_user_record` WHERE GRASS_DATE BETWEEN '2026-01-01' AND '2026-02-28' AND MAU_TYPE = '1.New' GROUP BY DATE_TRUNC(GRASS_DATE, MONTH) ) SELECT *, LAG(new_users) OVER (ORDER BY month) AS prev_month, new_users - LAG(new_users) OVER (ORDER BY month) AS diff FROM monthly_new | I32: 2 rows: Jan + Feb new user counts with diff | J32: 2 | K32: eval | L32: DA Team (AI-assisted) | M32: 46091 | N32: TTT
A33: TTT012 | B33: Góp chung (Money Pool) đang chiếm bao nhiêu % tổng AUM? | C33: Aggregation | D33: Simple | E33: mart_ttt_daily_user_record | F33: IS_MP, BALANCE, GRASS_DATE | G33: IS_MP = 'Money Pool' vs 'Individual'. AUM = snapshot cuối tháng. % = Money Pool AUM / Total AUM * 100. LLM có thể không biết column IS_MP tồn tại hoặc dùng sai filter. Nếu SUM across month → sai 30x nhưng tỷ lệ % có thể vẫn gần đúng (trap tinh vi). | H33: SELECT IS_MP, SUM(BALANCE) AS aum, SUM(BALANCE) * 100.0 / SUM(SUM(BALANCE)) OVER () AS pct FROM `momovn-prod.BU_FI.mart_ttt_daily_user_record` WHERE GRASS_DATE = '2026-01-31' GROUP BY IS_MP | I33: 2 rows: Individual ~86%, Money Pool ~14% | J33: 2 | K33: eval | L33: DA Team (AI-assisted) | M33: 46091 | N33: TTT
... A40: TTT019 | B40: Trong tháng 1, ngày nào có nhiều người rút tiền nhất? Rút bao nhiêu? | C40: Ranking + Filter | D40: Moderate | E40: mart_ttt_daily_user_record | F40: GRASS_DATE, USER_ID, cashout sub-channels | G40: Nhiều người rút = COUNT DISTINCT users có cashout > 0 (bất kỳ sub-channel nào). "Rút bao nhiêu" = total cashout GMV ngày đó (SUM tất cả 7 sub-channels). Cần cả 2 metrics: user count + GMV. Chỉ count users có ít nhất 1 cashout sub-channel > 0. REGEXP_EXTRACT. LLM thường chỉ trả GMV hoặc chỉ trả user count, không cả 2. | H40: SELECT GRASS_DATE, COUNT(DISTINCT CAST(REGEXP_EXTRACT(USER_ID, r'\d+') AS STRING)) AS users_withdrawing, SUM( COALESCE(cashout_gmv, 0) + COALESCE(cashout_napas_gmv, 0) + COALESCE(cashout_p2p_gmv, 0) + COALESCE(cashout_payment_gmv, 0) + COALESCE(cashout_stock_gmv, 0) + COALESCE(cashout_mp_gmv, 0) + COALESCE(cashout_payment_mp_gmv, 0) ) AS total_cashout FROM `momovn-prod.BU_FI.mart_ttt_daily_user_record` WHERE GRASS_DATE BETWEEN '2026-01-01' AND '2026-01-31' AND ( COALESCE(cashout_gmv, 0) + COALESCE(cashout_napas_gmv, 0) + COALESCE(cashout_p2p_gmv, 0) + COALESCE(cashout_payment_gmv, 0) + COALESCE(cashout_stock_gmv, 0) + COALESCE(cashout_mp_gmv, 0) + COALESCE(cashout_payment_mp_gmv, 0) ) > 0 GROUP BY GRASS_DATE ORDER BY users_withdrawing DESC LIMIT 1 | I40: 1 row: ngày peak + user count + total cashout GMV | J40: 1 | K40: eval | L40: DA Team (AI-assisted) | M40: 46091 | N40: TTT
A41: TTT020 | B41: TTT tháng vừa rồi ổn không? Brief cho t ngắn gọn | C41: Ambiguous | D41: Ambiguous | E41: mart_ttt_daily_user_record | F41: Potentially ALL | G41: Câu hỏi executive-style cực kỳ vague. "Tháng vừa rồi" = tháng nào? "Ổn không" = theo tiêu chí gì? Agent tốt nên: (1) clarify hoặc (2) decompose thành ≥3 metrics: MAU trend, AUM, net cash flow, churn. Nếu chỉ trả 1 metric → incomplete. Nếu tháng 3/2026 → net cash -416B là critical insight. Agent đúng khi hỏi ngược: "Anh muốn t nhìn vào chỉ số nào? MAU, AUM, hay dòng tiền?". | H41: -- Không có single Gold SQL -- Agent tốt: hỏi lại HOẶC chạy ≥3 queries: -- 1. MAU (with REGEXP_EXTRACT + MAU_TYPE filter) -- 2. AUM (end-of-month snapshot) -- 3. Net cash flow (full cashin - cashout sub-channels) -- 4. Churn rate (optional) | I41: Multi-query needed. Key: nếu Feb thì relatively stable; nếu Mar thì net cash -416B red flag | J41: N/A | K41: eval | L41: DA Team (AI-assisted) | M41: 46091 | N41: TTT
A42: TTT021 | B42: user ttt giu tien bao lau truoc khi rut ra het? | C42: Window + Complex | D42: Complex | E42: mart_ttt_daily_user_record | F42: USER_ID, BALANCE, MFU_TYPE, GRASS_DATE | G42: Câu hỏi hành vi duration — cần tính khoảng cách ngày từ lúc user bắt đầu có balance > 0 đến khi balance = 0. Table là daily snapshot nên phải self-join hoặc window function để tìm "first funded date" vs "last funded date" per user. Rất phức tạp: cần xác định "episode" nạp-rút, không phải chỉ min/max date. LLM sẽ gần như chắc chắn oversimplify hoặc viết sai logic. Có thể cần approximate bằng cách tính avg số ngày MFU_TYPE != '0.Churn' liên tiếp. | H42: -- Approximate: avg number of consecutive funded days per user WITH funded_days AS ( SELECT CAST(REGEXP_EXTRACT(USER_ID, r'\d+') AS STRING) AS uid, GRASS_DATE, MFU_TYPE, LAG(GRASS_DATE) OVER (PARTITION BY CAST(REGEXP_EXTRACT(USER_ID, r'\d+') AS STRING) ORDER BY GRASS_DATE) AS prev_date FROM `momovn-prod.BU_FI.mart_ttt_daily_user_record` WHERE GRASS_DATE BETWEEN '2026-01-01' AND '2026-01-31' AND MFU_TYPE != '0.Churn' ), with_gaps AS ( SELECT uid, GRASS_DATE, CASE WHEN DATE_DIFF(GRASS_DATE, prev_date, DAY) > 1 OR prev_date IS NULL THEN 1 ELSE 0 END AS new_episode FROM funded_days ), episodes AS ( SELECT uid, GRASS_DATE, SUM(new_episode) OVER (PARTITION BY uid ORDER BY GRASS_DATE) AS episode_id FROM with_gaps ), episode_length AS ( SELECT uid, episode_id, DATE_DIFF(MAX(GRASS_DATE), MIN(GRASS_DATE), DAY) + 1 AS days_held FROM episodes GROUP BY uid, episode_id ) SELECT AVG(days_held) AS avg_days_before_withdraw, APPROX_QUANTILES(days_held, 100)[OFFSET(50)] AS median_days FROM episode_length | I42: 1 row: avg + median days users hold money before withdrawing | J42: 1 | K42: eval | L42: DA Team (AI-assisted) | M42: 46091 | N42: TTT
A43: TTT022 | B43: tai sao aum giam thang nay? | C43: Ambiguous | D43: Ambiguous | E43: mart_ttt_daily_user_record | F43: BALANCE, GRASS_DATE, cashin/cashout sub-channels, MAU_TYPE, MFU_TYPE | G43: Câu hỏi causal ("tại sao") — SQL không trả lời được "tại sao", chỉ trả lời "cái gì xảy ra". Agent tốt nên: (1) Xác nhận AUM giảm thật không (snapshot cuối tháng so sánh), (2) Decompose các yếu tố: net cash flow giảm? user churn tăng? cashin giảm? cashout tăng? (3) Trả lời bằng data rồi interpret. "Tháng này" không rõ tháng nào. LLM sẽ fail nếu chỉ gen 1 query đơn giản. | H43: -- Cần multi-query decomposition. Minimum: -- 1. AUM comparison (2 tháng gần nhất, end-of-month snapshot) -- 2. Net cash flow breakdown (cashin vs cashout, all sub-channels) -- 3. MFU churn (người rút hết tiền) -- Không có single SQL answer cho "tại sao" | I43: Multi-query. Agent tốt nhất nên hỏi lại "tháng nào?" rồi decompose | J43: N/A | K43: eval | L43: DA Team (AI-assisted) | M43: 46091 | N43: TTT
A44: TTT023 | B44: moi thang co bao nhieu nguoi nap VA tren 10 giao dich 1 ngay? | C44: Aggregation | D44: Complex | E44: mart_ttt_daily_user_record | F44: USER_ID, CASHIN_VA_TRANS, GRASS_DATE | G44: Nạp VA = Virtual Account cashin. "Trên 10 giao dịch 1 ngày" = CASHIN_VA_TRANS > 10 per row (vì mỗi row = 1 user/1 ngày). Cần GROUP BY tháng, COUNT DISTINCT user có ít nhất 1 ngày CASHIN_VA_TRANS > 10. REGEXP_EXTRACT cho dedup. Câu hỏi cụ thể nhưng dùng column TRANS (không phải GMV) — LLM thường chỉ biết GMV columns. "Mỗi tháng" = cần multi-month, không nói range → agent phải infer. | H44: SELECT DATE_TRUNC(GRASS_DATE, MONTH) AS month, COUNT(DISTINCT CAST(REGEXP_EXTRACT(USER_ID, r'\d+') AS STRING)) AS users_over_10_va_trans FROM `momovn-prod.BU_FI.mart_ttt_daily_user_record` WHERE GRASS_DATE BETWEEN '2025-10-01' AND '2026-02-28' AND CASHIN_VA_TRANS > 10 GROUP BY DATE_TRUNC(GRASS_DATE, MONTH) ORDER BY month | I44: ~5 rows (1 per month), count users with >10 VA transactions in a single day | J44: 5 | K44: eval | L44: DA Team (AI-assisted) | M44: 46091 | N44: TTT
